Workbook

Sheet Cover
A3: Track
A4: 1 | B4: =HYPERLINK("#'Dashboard'!A1","Dashboard") -> Dashboard | C4: money · people · risks
A5: 2 | B5: =HYPERLINK("#'Channel_Pivot'!A1","Channel_Pivot") -> Channel_Pivot | C5: which channel pays
A6: 3 | B6: =HYPERLINK("#'First30'!A1","First30") -> First30 | C6: start here
A7: 4 | B7: =HYPERLINK("#'Gantt'!A1","Gantt") -> Gantt | C7: overall plan
A8: 5 | B8: =HYPERLINK("#'Sales2027'!A1","Sales2027") -> Sales2027 | C8: Sales Plan 2027
A9: 6 | B9: =HYPERLINK("#'PnL2027'!A1","PnL2027") -> PnL2027 | C9: costs + net
A10: Work
A11: 7 | B11: =HYPERLINK("#'Leads'!A1","Leads") -> Leads | C11: pipeline
A12: 8 | B12: =HYPERLINK("#'Trials'!A1","Trials") -> Trials | C12: booking + outcome
A13: 9 | B13: =HYPERLINK("#'Invoices'!A1","Invoices") -> Invoices | C13: bill + collect
A14: 10 | B14: =HYPERLINK("#'Students'!A1","Students") -> Students | C14: credits left
A15: 11 | B15: =HYPERLINK("#'Makeup_Churn'!A1","Makeup_Churn") -> Makeup_Churn | C15: who drifts
A16: 12 | B16: =HYPERLINK("#'Expenses'!A1","Expenses") -> Expenses | C16: spend
A17: 13 | B17: =HYPERLINK("#'WinterCamp'!A1","WinterCamp") -> WinterCamp | C17: full
A18: 14 | B18: =HYPERLINK("#'Camp_Plan'!A1","Camp_Plan") -> Camp_Plan | C18: 6-step plan
A19: Send
A20: 15 | B20: =HYPERLINK("#'Scripts'!A1","Scripts") -> Scripts
A21: 16 | B21: =HYPERLINK("#'Send_Kit'!A1","Send_Kit") -> Send_Kit | C21: Kits
A22: 17 | B22: =HYPERLINK("#'SOP'!A1","SOP") -> SOP | C22: 8 steps daily
A23: Program
A24: 18 | B24: =HYPERLINK("#'Programs'!A1","Programs") -> Programs | C24: Programs
A25: 19 | B25: =HYPERLINK("#'Exhibitions'!A1","Exhibitions") -> Exhibitions | C25: Exhibitions
A26: 20 | B26: =HYPERLINK("#'Certificates'!A1","Certificates") -> Certificates | C26: Certificates Tracker
A27: 21 | B27: =HYPERLINK("#'Certificate'!A1","Certificate") -> Certificate | C27: print certificate
A28: 22 | B28: =HYPERLINK("#'Calendar'!A1","Calendar") -> Calendar | C28: year calendar
A29: 23 | B29: =HYPERLINK("#'Showcase'!A1","Showcase") -> Showcase | C29: art party plan
A30: 24 | B30: =HYPERLINK("#'BirthdayWS'!A1","BirthdayWS") -> BirthdayWS | C30: birthday plan
A31: 25 | B31: =HYPERLINK("#'HalloweenPlan'!A1","HalloweenPlan") -> HalloweenPlan | C31: pumpkin plan
A32: Assets
A33: 26 | B33: =HYPERLINK("#'Assets'!A1","Assets") -> Assets | C33: Assets Control
A34: 27 | B34: =HYPERLINK("#'PDF_List'!A1","PDF_List") -> PDF_List | C34: missing list
A35: 28 | B35: =HYPERLINK("#'Flyer'!A1","Flyer") -> Flyer | C35: trial flyer
A36: 29 | B36: =HYPERLINK("#'Halloween'!A1","Halloween") -> Halloween | C36: pumpkin flyer
A37: 30 | B37: =HYPERLINK("#'ForFun_EN'!A1","ForFun_EN") -> ForFun_EN | C37: for fun
A38: 31 | B38: =HYPERLINK("#'Events'!A1","Events") -> Events | C38: events + gifts
A39: 32 | B39: =HYPERLINK("#'Brand'!A1","Brand") -> Brand | C39: logo + sign-offs
A40: 33 | B40: =HYPERLINK("#'Invoice_Poster'!A1","Invoice_Poster") -> Invoice_Poster | C40: print invoice
A41: 34 | B41: =HYPERLINK("#'Consent_Poster'!A1","Consent_Poster") -> Consent_Poster | C41: print consent
A42: 35 | B42: =HYPERLINK("#'Survey_Poster'!A1","Survey_Poster") -> Survey_Poster | C42: print
...

Sheet Dashboard
A1: Dashboard | D1: =HYPERLINK("#'Cover'!A1","←") -> ←
A2: Item | B2: Amount (¥) | C2: Notes
A3: Month revenue (paid) | B3: =SUMIF(Invoices!I3:I34,"Paid",Invoices!H3:H34) -> 8000
A4: Outstanding (unpaid) | B4: =SUMIF(Invoices!I3:I34,"Unpaid",Invoices!H3:H34) -> 0 | C4: ¥ — chase now
A5: Other expenses | B5: =SUM(Expenses!D3:D100) -> 0 | C5: ¥ — auto from Expenses
A6: Referral payout 10% | B6: =B3*0.1 -> 800 | C6: ¥
A7: Hospitality 3% | B7: =B3*0.03 -> 240 | C7: ¥
A8: Net balance | B8: =B3-B4-B5-B6-B7 -> 6960 | C8: ¥ — revenue minus all
A9: Active students | B9: =COUNTA(Students!A3:A100) -> 5 | C9: kids
A10: Open leads | B10: =COUNTIF(Leads!G3:G100,"Contacting")+COUNTIF(Leads!G3:G100,"Trial booked") -> 1 | C10: families
A11: Trial→enrolment | B11: =IFERROR(COUNTIF(Trials!F3:F100,"Enrolled")/COUNTA(Trials!A3:A100),0) -> 0.5 | C11: target 50%
A12: Renewals due | B12: =COUNTIF(Students!J3:J100,"Renew now") -> 0 | C12: kids — see Students
A13: Renew soon (4 left — act early) | B13: =COUNTIF(Students!J3:J100,"Renew soon") -> 0 | C13: families — talk before the last 2
A14: Churn risks | B14: =COUNTIF(Makeup_Churn!F3:F100,"At risk — talk now") -> 0 | C14: families
A15: Camp weeks full | B15: =COUNTIF(WinterCamp!G3:G100,"Full") -> 0 | C15: weeks ≥4 kids
A16: Renew now list | B16: =IF(COUNTIF(Students!J3:J100,"Renew now")=0,"--",INDEX(Students!B3:B100,MATCH("Renew now",Students!J3:J100,0))&" +"&COUNTIF(Students!J3:J100,"Renew now")&" kids") -> -- | C16: List (auto in modern WPS; else see red rows)
A17: Churn watchlist | B17: =IF(COUNTIF(Makeup_Churn!F3:F100,"At risk — talk now")=0,"--",INDEX(Makeup_Churn!A3:A100,MATCH("At risk — talk now",Makeup_Churn!F3:F100,0))&" +"&COUNTIF(Makeup_Churn!F3:F100,"At risk — talk now")&" families") -> -- | C17: List (auto in modern WPS; else see red rows)
A18: Outstanding detail | B18: =IF(COUNTIF(Invoices!I3:I34,"Unpaid")=0,"--",INDEX(Invoices!C3:C34,MATCH("Unpaid",Invoices!I3:I34,0))&" +"&COUNTIF(Invoices!I3:I34,"Unpaid")&" invoices") -> -- | C18: Detail (auto; else see Unpaid rows)
A19: Today's list (auto) | D19: Done?
A20: Renew now: call red rows in Students | B20: =COUNTIF(Students!J3:J100,"Renew now")&" kids" -> 0 kids
A21: At risk: talk to red rows in Makeup_Churn | B21: =COUNTIF(Makeup_Churn!F3:F100,"At risk — talk now")&" families" -> 0 families
A22: Unpaid: chase Unpaid rows in Invoices | B22: =COUNTIF(Invoices!I3:I34,"Unpaid")&" invoices" -> 0 invoices
A24: Targets vs Actual (meeting numbers)
A25: Metric | B25: Target | C25: Actual | D25: Gap
A26: Students / month | B26: 15 | C26: =COUNTA(Students!A3:A100) -> 5 | D26: =C25-B25 -> #VALUE!
A27: Trial conversion | B27: 0.5 | C27: =IFERROR(COUNTIF(Trials!F3:F100,"Enrolled")/MAX(1,COUNTA(Trials!A3:A100)),0) -> 0.5 | D27: =C26-B26 -> -10
A28: Camp weeks full | B28: 2 | C28: =COUNTIF(WinterCamp!G3:G100,"Full") -> 0 | D28: =C27-B27 -> 0
A29: Renewals due (want 0) | B29: 0 | C29: =COUNTIF(Students!J3:J100,"Renew now") -> 0 | D29: =C28-B28 -> -2
A30: Churn risks (want 0) | B30: 0 | C30: =COUNTIF(Makeup_Churn!F3:F100,"At risk — talk now") -> 0 | D30: =C29-B29 -> 0
A31: Unpaid bills (want 0) | B31: 0 | C31: =COUNTIF(Invoices!I3:I34,"Unpaid") -> 0 | D31: =C30-B30 -> 0
A32: Open items (want 0): renewals, risks, unpaid above. | B32: 24 hours | C32: Target (meeting)

Sheet Students
A1: Students & Class Credits | M1: =HYPERLINK("#'Cover'!A1","←") -> ←
A2: ID | B2: Name | C2: Age | D2: School | E2: WeChat | F2: Package | G2: Total | H2: Used | I2: Left | J2: Renew flag | K2: From trial | L2: Absences
A3: STU-01 | B3: Josh D1 | C3: 7 | D3: Dulwich | F3: Semester+1 | G3: 20 | H3: 6 | I3: =IF(G3="","",G3-H3) -> 14 | J3: =IF(I3="","",IF(I3<=2,"Renew now",IF(I3<=4,"Renew soon","OK"))) -> OK | K3: =IF(B3="","",IFERROR(INDEX(Trials!A$3:A$50,MATCH("*"&B3&"*",Trials!C$3:C$50,0)),"")) -> TR-01
A4: STU-02 | B4: Josh D2 | C4: 6 | D4: Dulwich | F4: Semester | G4: 12 | H4: 0 | I4: =IF(G4="","",G4-H4) -> 12 | J4: =IF(I4="","",IF(I4<=2,"Renew now",IF(I4<=4,"Renew soon","OK"))) -> OK | K4: =IF(B4="","",IFERROR(INDEX(Trials!A$3:A$50,MATCH("*"&B4&"*",Trials!C$3:C$50,0)),"")) | L4: =IF(B4="","",SUMIF(Makeup_Churn!A$3:A$100,B4,Makeup_Churn!C$3:C$100)) -> 0
A5: STU-03 | B5: Charlotte | C5: 5 | D5: Dulwich | F5: Semester | G5: 12 | H5: 0 | I5: =IF(G5="","",G5-H5) -> 12 | J5: =IF(I5="","",IF(I5<=2,"Renew now",IF(I5<=4,"Renew soon","OK"))) -> OK | K5: =IF(B5="","",IFERROR(INDEX(Trials!A$3:A$50,MATCH("*"&B5&"*",Trials!C$3:C$50,0)),"")) | L5: =IF(B5="","",SUMIF(Makeup_Churn!A$3:A$100,B5,Makeup_Churn!C$3:C$100)) -> 0
A6: STU-04 | B6: William | C6: 7 | D6: Dulwich | F6: Semester | G6: 12 | H6: 0 | I6: =IF(G6="","",G6-H6) -> 12 | J6: =IF(I6="","",IF(I6<=2,"Renew now",IF(I6<=4,"Renew soon","OK"))) -> OK | K6: =IF(B6="","",IFERROR(INDEX(Trials!A$3:A$50,MATCH("*"&B6&"*",Trials!C$3:C$50,0)),"")) | L6: =IF(B6="","",SUMIF(Makeup_Churn!A$3:A$100,B6,Makeup_Churn!C$3:C$100)) -> 0
A7: STU-05 | B7: Daphne | C7: 9 | D7: YCIS | F7: 18-class | G7: 18 | H7: 4 | I7: =IF(G7="","",G7-H7) -> 14 | J7: =IF(I7="","",IF(I7<=2,"Renew now",IF(I7<=4,"Renew soon","OK"))) -> OK | K7: =IF(B7="","",IFERROR(INDEX(Trials!A$3:A$50,MATCH("*"&B7&"*",Trials!C$3:C$50,0)),"")) | L7: =IF(B7="","",SUMIF(Makeup_Churn!A$3:A$100,B7,Makeup_Churn!C$3:C$100)) -> 0
I8: =IF(G8="","",G8-H8) | J8: =IF(I8="","",IF(I8<=2,"Renew now",IF(I8<=4,"Renew soon","OK"))) | K8: =IF(B8="","",IFERROR(INDEX(Trials!A$3:A$50,MATCH("*"&B8&"*",Trials!C$3:C$50,0)),"")) | L8: =IF(B8="","",SUMIF(Makeup_Churn!A$3:A$100,B8,Makeup_Churn!C$3:C$100))
I9: =IF(G9="","",G9-H9) | J9: =IF(I9="","",IF(I9<=2,"Renew now",IF(I9<=4,"Renew soon","OK"))) | K9: =IF(B9="","",IFERROR(INDEX(Trials!A$3:A$50,MATCH("*"&B9&"*",Trials!C$3:C$50,0)),"")) | L9: =IF(B9="","",SUMIF(Makeup_Churn!A$3:A$100,B9,Makeup_Churn!C$3:C$100))
I10: =IF(G10="","",G10-H10) | J10: =IF(I10="","",IF(I10<=2,"Renew now",IF(I10<=4,"Renew soon","OK"))) | K10: =IF(B10="","",IFERROR(INDEX(Trials!A$3:A$50,MATCH("*"&B10&"*",Trials!C$3:C$50,0)),"")) | L10: =IF(B10="","",SUMIF(Makeup_Churn!A$3:A$100,B10,Makeup_Churn!C$3:C$100))
I11: =IF(G11="","",G11-H11) | J11: =IF(I11="","",IF(I11<=2,"Renew now",IF(I11<=4,"Renew soon","OK"))) | K11: =IF(B11="","",IFERROR(INDEX(Trials!A$3:A$50,MATCH("*"&B11&"*",Trials!C$3:C$50,0)),"")) | L11: =IF(B11="","",SUMIF(Makeup_Churn!A$3:A$100,B11,Makeup_Churn!C$3:C$100))
I12: =IF(G12="","",G12-H12) | J12: =IF(I12="","",IF(I12<=2,"Renew now",IF(I12<=4,"Renew soon","OK"))) | K12: =IF(B12="","",IFERROR(INDEX(Trials!A$3:A$50,MATCH("*"&B12&"*",Trials!C$3:C$50,0)),"")) | L12: =IF(B12="","",SUMIF(Makeup_Churn!A$3:A$100,B12,Makeup_Churn!C$3:C$100))
I13: =IF(G13="","",G13-H13) | J13: =IF(I13="","",IF(I13<=2,"Renew now",IF(I13<=4,"Renew soon","OK"))) | K13: =IF(B13="","",IFERROR(INDEX(Trials!A$3:A$50,MATCH("*"&B13&"*",Trials!C$3:C$50,0)),"")) | L13: =IF(B13="","",SUMIF(Makeup_Churn!A$3:A$100,B13,Makeup_Churn!C$3:C$100))
I14: =IF(G14="","",G14-H14) | J14: =IF(I14="","",IF(I14<=2,"Renew now",IF(I14<=4,"Renew soon","OK"))) | K14: =IF(B14="","",IFERROR(INDEX(Trials!A$3:A$50,MATCH("*"&B14&"*",Trials!C$3:C$50,0)),"")) | L14: =IF(B14="","",SUMIF(Makeup_Churn!A$3:A$100,B14,Makeup_Churn!C$3:C$100))
I15: =IF(G15="","",G15-H15) | J15: =IF(I15="","",IF(I15<=2,"Renew now",IF(I15<=4,"Renew soon","OK"))) | K15: =IF(B15="","",IFERROR(INDEX(Trials!A$3:A$50,MATCH("*"&B15&"*",Trials!C$3:C$50,0)),"")) | L15: =IF(B15="","",SUMIF(Makeup_Churn!A$3:A$100,B15,Makeup_Churn!C$3:C$100))
I16: =IF(G16="","",G16-H16) | J16: =IF(I16="","",IF(I16<=2,"Renew now",IF(I16<=4,"Renew soon","OK"))) | K16: =IF(B16="","",IFERROR(INDEX(Trials!A$3:A$50,MATCH("*"&B16&"*",Trials!C$3:C$50,0)),"")) | L16: =IF(B16="","",SUMIF(Makeup_Churn!A$3:A$100,B16,Makeup_Churn!C$3:C$100))
I17: =IF(G17="","",G17-H17) | J17: =IF(I17="","",IF(I17<=2,"Renew now",IF(I17<=4,"Renew soon","OK"))) | K17: =IF(B17="","",IFERROR(INDEX(Trials!A$3:A$50,MATCH("*"&B17&"*",Trials!C$3:C$50,0)),"")) | L17: =IF(B17="","",SUMIF(Makeup_Churn!A$3:A$100,B17,Makeup_Churn!C$3:C$100))
I18: =IF(G18="","",G18-H18) | J18: =IF(I18="","",IF(I18<=2,"Renew now",IF(I18<=4,"Renew soon","OK"))) | K18: =IF(B18="","",IFERROR(INDEX(Trials!A$3:A$50,MATCH("*"&B18&"*",Trials!C$3:C$50,0)),"")) | L18: =IF(B18="","",SUMIF(Makeup_Churn!A$3:A$100,B18,Makeup_Churn!C$3:C$100))
I19: =IF(G19="","",G19-H19) | J19: =IF(I19="","",IF(I19<=2,"Renew now",IF(I19<=4,"Renew soon","OK"))) | K19: =IF(B19="","",IFERROR(INDEX(Trials!A$3:A$50,MATCH("*"&B19&"*",Trials!C$3:C$50,0)),"")) | L19: =IF(B19="","",SUMIF(Makeup_Churn!A$3:A$100,B19,Makeup_Churn!C$3:C$100))
... I32: =IF(G32="","",G32-H32) | J32: =IF(I32="","",IF(I32<=2,"Renew now",IF(I32<=4,"Renew soon","OK"))) | K32: =IF(B32="","",IFERROR(INDEX(Trials!A$3:A$50,MATCH("*"&B32&"*",Trials!C$3:C$50,0)),"")) | L32: =IF(B32="","",SUMIF(Makeup_Churn!A$3:A$100,B32,Makeup_Churn!C$3:C$100))
I33: =IF(G33="","",G33-H33) | K33: =IF(B33="","",IFERROR(INDEX(Trials!A$3:A$50,MATCH("*"&B33&"*",Trials!C$3:C$50,0)),""))
I34: =IF(G34="","",G34-H34) | K34: =IF(B34="","",IFERROR(INDEX(Trials!A$3:A$50,MATCH("*"&B34&"*",Trials!C$3:C$50,0)),""))
I35: =IF(G35="","",G35-H35) | K35: =IF(B35="","",IFERROR(INDEX(Trials!A$3:A$50,MATCH("*"&B35&"*",Trials!C$3:C$50,0)),""))
I36: =IF(G36="","",G36-H36) | K36: =IF(B36="","",IFERROR(INDEX(Trials!A$3:A$50,MATCH("*"&B36&"*",Trials!C$3:C$50,0)),""))
I37: =IF(G37="","",G37-H37) | K37: =IF(B37="","",IFERROR(INDEX(Trials!A$3:A$50,MATCH("*"&B37&"*",Trials!C$3:C$50,0)),""))
I38: =IF(G38="","",G38-H38) | K38: =IF(B38="","",IFERROR(INDEX(Trials!A$3:A$50,MATCH("*"&B38&"*",Trials!C$3:C$50,0)),""))
I39: =IF(G39="","",G39-H39) | K39: =IF(B39="","",IFERROR(INDEX(Trials!A$3:A$50,MATCH("*"&B39&"*",Trials!C$3:C$50,0)),""))
I40: =IF(G40="","",G40-H40) | K40: =IF(B40="","",IFERROR(INDEX(Trials!A$3:A$50,MATCH("*"&B40&"*",Trials!C$3:C$50,0)),""))
I41: =IF(G41="","",G41-H41) | K41: =IF(B41="","",IFERROR(INDEX(Trials!A$3:A$50,MATCH("*"&B41&"*",Trials!C$3:C$50,0)),""))
I42: =IF(G42="","",G42-H42) | K42: =IF(B42="","",IFERROR(INDEX(Trials!A$3:A$50,MATCH("*"&B42&"*",Trials!C$3:C$50,0)),""))
I43: =IF(G43="","",G43-H43) | K43: =IF(B43="","",IFERROR(INDEX(Trials!A$3:A$50,MATCH("*"&B43&"*",Trials!C$3:C$50,0)),""))
I44: =IF(G44="","",G44-H44) | K44: =IF(B44="","",IFERROR(INDEX(Trials!A$3:A$50,MATCH("*"&B44&"*",Trials!C$3:C$50,0)),""))
... I100: =IF(G100="","",G100-H100) | K100: =IF(B100="","",IFERROR(INDEX(Trials!A$3:A$50,MATCH("*"&B100&"*",Trials!C$3:C$50,0)),""))

Sheet Leads
A1: Leads | M1: =HYPERLINK("#'Cover'!A1","←") -> ←
A2: Lead ID | B2: Parent | C2: Child / Age | D2: School | E2: Source | F2: CCA? | G2: Status | H2: Next step | I2: Last follow-up | J2: Introduced by | K2: Owner | L2: First-touch script
A3: LEAD-01 | B3: Josh's dad | C3: Josh D1, 7 | D3: Dulwich | E3: Referral | F3: No | G3: Enrolled | H3: Collect 4-kid fees
A4: LEAD-02 | B4: Pending A | E4: CCA showcase | F4: Yes | G4: Contacting | H4: Invite to visit | K4: Studio official | L4: =IF(F4="Yes",IFERROR(VLOOKUP("C1",Scripts!A$3:D$60,3,FALSE),""),"") -> You're warmly invited: our end-of-term mini exhibition opens Saturday afternoon, and [child] has work in it. Come hear them talk it through for five minutes — grandparents very welcome too. Afterwards, come upstairs and see the studio.
L5: =IF(F5="Yes",IFERROR(VLOOKUP("C1",Scripts!A$3:D$60,3,FALSE),""),"")
L6: =IF(F6="Yes",IFERROR(VLOOKUP("C1",Scripts!A$3:D$60,3,FALSE),""),"")
L7: =IF(F7="Yes",IFERROR(VLOOKUP("C1",Scripts!A$3:D$60,3,FALSE),""),"")
L8: =IF(F8="Yes",IFERROR(VLOOKUP("C1",Scripts!A$3:D$60,3,FALSE),""),"")
L9: =IF(F9="Yes",IFERROR(VLOOKUP("C1",Scripts!A$3:D$60,3,FALSE),""),"")
L10: =IF(F10="Yes",IFERROR(VLOOKUP("C1",Scripts!A$3:D$60,3,FALSE),""),"")
L11: =IF(F11="Yes",IFERROR(VLOOKUP("C1",Scripts!A$3:D$60,3,FALSE),""),"")
L12: =IF(F12="Yes",IFERROR(VLOOKUP("C1",Scripts!A$3:D$60,3,FALSE),""),"")
L13: =IF(F13="Yes",IFERROR(VLOOKUP("C1",Scripts!A$3:D$60,3,FALSE),""),"")
L14: =IF(F14="Yes",IFERROR(VLOOKUP("C1",Scripts!A$3:D$60,3,FALSE),""),"")
L15: =IF(F15="Yes",IFERROR(VLOOKUP("C1",Scripts!A$3:D$60,3,FALSE),""),"")
L16: =IF(F16="Yes",IFERROR(VLOOKUP("C1",Scripts!A$3:D$60,3,FALSE),""),"")
... L100: =IF(F100="Yes",IFERROR(VLOOKUP("C1",Scripts!A$3:D$60,3,FALSE),""),"")

Sheet Trials
A1: Trials | K1: =HYPERLINK("#'Cover'!A1","←") -> ←
A2: Trial ID | B2: Lead ID | C2: Child | D2: Date | E2: Attended | F2: Outcome | G2: No-enrol reason | H2: Script | I2: Script CN | J2: Script EN
A3: TR-01 | B3: LEAD-01 | C3: =IF(B3="","",IFERROR(VLOOKUP(B3,Leads!A$3:C$100,3,FALSE),"")) -> Josh D1, 7 | D3: 2026-10-18 | E3: Attended | F3: Enrolled | H3: T1
A4: TR-02 | B4: LEAD-02 | C4: =IF(B4="","",IFERROR(VLOOKUP(B4,Leads!A$3:C$100,3,FALSE),"")) | D4: 2026-10-19 | E4: Attended | F4: Not enrolled | G4: Schedule clash | H4: T2 | I4: =IF(H4="","",IFERROR(VLOOKUP(H4,Scripts!A$3:D$60,3,FALSE),"")) -> No pressure at all — art can't be rushed. If you have a moment, tell me what held you back (timing, fee, or simply not yet) so I can note it. When a camp or workshop fits, you'll hear from me first. | J4: =IF(H4="","",IFERROR(VLOOKUP(H4,Scripts!A$3:D$60,4,FALSE),"")) -> 完全没关系，艺术急不得。方便的话告诉我一声，是时间、费用，还是时机未到，我记下来。以后有合适的营或工坊，我第一个告诉您。
C5: =IF(B5="","",IFERROR(VLOOKUP(B5,Leads!A$3:C$100,3,FALSE),"")) | I5: =IF(H5="","",IFERROR(VLOOKUP(H5,Scripts!A$3:D$60,3,FALSE),"")) | J5: =IF(H5="","",IFERROR(VLOOKUP(H5,Scripts!A$3:D$60,4,FALSE),""))
C6: =IF(B6="","",IFERROR(VLOOKUP(B6,Leads!A$3:C$100,3,FALSE),"")) | I6: =IF(H6="","",IFERROR(VLOOKUP(H6,Scripts!A$3:D$60,3,FALSE),"")) | J6: =IF(H6="","",IFERROR(VLOOKUP(H6,Scripts!A$3:D$60,4,FALSE),""))
C7: =IF(B7="","",IFERROR(VLOOKUP(B7,Leads!A$3:C$100,3,FALSE),"")) | I7: =IF(H7="","",IFERROR(VLOOKUP(H7,Scripts!A$3:D$60,3,FALSE),"")) | J7: =IF(H7="","",IFERROR(VLOOKUP(H7,Scripts!A$3:D$60,4,FALSE),""))
C8: =IF(B8="","",IFERROR(VLOOKUP(B8,Leads!A$3:C$100,3,FALSE),"")) | I8: =IF(H8="","",IFERROR(VLOOKUP(H8,Scripts!A$3:D$60,3,FALSE),"")) | J8: =IF(H8="","",IFERROR(VLOOKUP(H8,Scripts!A$3:D$60,4,FALSE),""))
C9: =IF(B9="","",IFERROR(VLOOKUP(B9,Leads!A$3:C$100,3,FALSE),"")) | I9: =IF(H9="","",IFERROR(VLOOKUP(H9,Scripts!A$3:D$60,3,FALSE),"")) | J9: =IF(H9="","",IFERROR(VLOOKUP(H9,Scripts!A$3:D$60,4,FALSE),""))
C10: =IF(B10="","",IFERROR(VLOOKUP(B10,Leads!A$3:C$100,3,FALSE),"")) | I10: =IF(H10="","",IFERROR(VLOOKUP(H10,Scripts!A$3:D$60,3,FALSE),"")) | J10: =IF(H10="","",IFERROR(VLOOKUP(H10,Scripts!A$3:D$60,4,FALSE),""))
C11: =IF(B11="","",IFERROR(VLOOKUP(B11,Leads!A$3:C$100,3,FALSE),"")) | I11: =IF(H11="","",IFERROR(VLOOKUP(H11,Scripts!A$3:D$60,3,FALSE),"")) | J11: =IF(H11="","",IFERROR(VLOOKUP(H11,Scripts!A$3:D$60,4,FALSE),""))
C12: =IF(B12="","",IFERROR(VLOOKUP(B12,Leads!A$3:C$100,3,FALSE),"")) | I12: =IF(H12="","",IFERROR(VLOOKUP(H12,Scripts!A$3:D$60,3,FALSE),"")) | J12: =IF(H12="","",IFERROR(VLOOKUP(H12,Scripts!A$3:D$60,4,FALSE),""))
C13: =IF(B13="","",IFERROR(VLOOKUP(B13,Leads!A$3:C$100,3,FALSE),"")) | I13: =IF(H13="","",IFERROR(VLOOKUP(H13,Scripts!A$3:D$60,3,FALSE),"")) | J13: =IF(H13="","",IFERROR(VLOOKUP(H13,Scripts!A$3:D$60,4,FALSE),""))
C14: =IF(B14="","",IFERROR(VLOOKUP(B14,Leads!A$3:C$100,3,FALSE),"")) | I14: =IF(H14="","",IFERROR(VLOOKUP(H14,Scripts!A$3:D$60,3,FALSE),"")) | J14: =IF(H14="","",IFERROR(VLOOKUP(H14,Scripts!A$3:D$60,4,FALSE),""))
C15: =IF(B15="","",IFERROR(VLOOKUP(B15,Leads!A$3:C$100,3,FALSE),"")) | I15: =IF(H15="","",IFERROR(VLOOKUP(H15,Scripts!A$3:D$60,3,FALSE),"")) | J15: =IF(H15="","",IFERROR(VLOOKUP(H15,Scripts!A$3:D$60,4,FALSE),""))
C16: =IF(B16="","",IFERROR(VLOOKUP(B16,Leads!A$3:C$100,3,FALSE),"")) | I16: =IF(H16="","",IFERROR(VLOOKUP(H16,Scripts!A$3:D$60,3,FALSE),"")) | J16: =IF(H16="","",IFERROR(VLOOKUP(H16,Scripts!A$3:D$60,4,FALSE),""))
... C32: =IF(B32="","",IFERROR(VLOOKUP(B32,Leads!A$3:C$100,3,FALSE),"")) | I32: =IF(H32="","",IFERROR(VLOOKUP(H32,Scripts!A$3:D$60,3,FALSE),"")) | J32: =IF(H32="","",IFERROR(VLOOKUP(H32,Scripts!A$3:D$60,4,FALSE),""))
I33: =IF(H33="","",IFERROR(VLOOKUP(H33,Scripts!A$3:D$60,3,FALSE),"")) | J33: =IF(H33="","",IFERROR(VLOOKUP(H33,Scripts!A$3:D$60,4,FALSE),""))
I34: =IF(H34="","",IFERROR(VLOOKUP(H34,Scripts!A$3:D$60,3,FALSE),"")) | J34: =IF(H34="","",IFERROR(VLOOKUP(H34,Scripts!A$3:D$60,4,FALSE),""))
I35: =IF(H35="","",IFERROR(VLOOKUP(H35,Scripts!A$3:D$60,3,FALSE),"")) | J35: =IF(H35="","",IFERROR(VLOOKUP(H35,Scripts!A$3:D$60,4,FALSE),""))
I36: =IF(H36="","",IFERROR(VLOOKUP(H36,Scripts!A$3:D$60,3,FALSE),"")) | J36: =IF(H36="","",IFERROR(VLOOKUP(H36,Scripts!A$3:D$60,4,FALSE),""))
I37: =IF(H37="","",IFERROR(VLOOKUP(H37,Scripts!A$3:D$60,3,FALSE),"")) | J37: =IF(H37="","",IFERROR(VLOOKUP(H37,Scripts!A$3:D$60,4,FALSE),""))
I38: =IF(H38="","",IFERROR(VLOOKUP(H38,Scripts!A$3:D$60,3,FALSE),"")) | J38: =IF(H38="","",IFERROR(VLOOKUP(H38,Scripts!A$3:D$60,4,FALSE),""))
I39: =IF(H39="","",IFERROR(VLOOKUP(H39,Scripts!A$3:D$60,3,FALSE),"")) | J39: =IF(H39="","",IFERROR(VLOOKUP(H39,Scripts!A$3:D$60,4,FALSE),""))
I40: =IF(H40="","",IFERROR(VLOOKUP(H40,Scripts!A$3:D$60,3,FALSE),"")) | J40: =IF(H40="","",IFERROR(VLOOKUP(H40,Scripts!A$3:D$60,4,FALSE),""))
I41: =IF(H41="","",IFERROR(VLOOKUP(H41,Scripts!A$3:D$60,3,FALSE),"")) | J41: =IF(H41="","",IFERROR(VLOOKUP(H41,Scripts!A$3:D$60,4,FALSE),""))
I42: =IF(H42="","",IFERROR(VLOOKUP(H42,Scripts!A$3:D$60,3,FALSE),"")) | J42: =IF(H42="","",IFERROR(VLOOKUP(H42,Scripts!A$3:D$60,4,FALSE),""))
I43: =IF(H43="","",IFERROR(VLOOKUP(H43,Scripts!A$3:D$60,3,FALSE),"")) | J43: =IF(H43="","",IFERROR(VLOOKUP(H43,Scripts!A$3:D$60,4,FALSE),""))
I44: =IF(H44="","",IFERROR(VLOOKUP(H44,Scripts!A$3:D$60,3,FALSE),"")) | J44: =IF(H44="","",IFERROR(VLOOKUP(H44,Scripts!A$3:D$60,4,FALSE),""))
... I100: =IF(H100="","",IFERROR(VLOOKUP(H100,Scripts!A$3:D$60,3,FALSE),"")) | J100: =IF(H100="","",IFERROR(VLOOKUP(H100,Scripts!A$3:D$60,4,FALSE),""))

Sheet Invoices
A1: Invoices | Q1: =HYPERLINK("#'Cover'!A1","←") -> ←
A2: Invoice No. | B2: Date | C2: Student | D2: Package | E2: Price | F2: Qty | G2: Discount | H2: Total | I2: Paid | J2: Paid date | K2: Script No. | L2: Script CN | M2: Source | N2: Approved by | O2: Script EN | P2: Type
A3: INV-2026-001 | C3: Josh D1 | E3: 400 | F3: 20 | G3: 0 | H3: =IF(E3="","",E3*IF(F3="",0,F3)-IF(G3="",0,G3)) -> 8000 | I3: Paid | K3: P1 | M3: Referral
D4: =IF(C4="","",IFERROR(VLOOKUP(C4,Students!B$3:F$100,5,FALSE),"")) | H4: =IF(E4="","",E4*IF(F4="",0,F4)-IF(G4="",0,G4)) | L4: =IF(K4="","",IFERROR(VLOOKUP(K4,Scripts!A$3:D$60,3,FALSE),"")) | O4: =IF(K4="","",IFERROR(VLOOKUP(K4,Scripts!A$3:D$60,4,FALSE),""))
D5: =IF(C5="","",IFERROR(VLOOKUP(C5,Students!B$3:F$100,5,FALSE),"")) | H5: =IF(E5="","",E5*IF(F5="",0,F5)-IF(G5="",0,G5)) | L5: =IF(K5="","",IFERROR(VLOOKUP(K5,Scripts!A$3:D$60,3,FALSE),"")) | O5: =IF(K5="","",IFERROR(VLOOKUP(K5,Scripts!A$3:D$60,4,FALSE),""))
D6: =IF(C6="","",IFERROR(VLOOKUP(C6,Students!B$3:F$100,5,FALSE),"")) | H6: =IF(E6="","",E6*IF(F6="",0,F6)-IF(G6="",0,G6)) | L6: =IF(K6="","",IFERROR(VLOOKUP(K6,Scripts!A$3:D$60,3,FALSE),"")) | O6: =IF(K6="","",IFERROR(VLOOKUP(K6,Scripts!A$3:D$60,4,FALSE),""))
D7: =IF(C7="","",IFERROR(VLOOKUP(C7,Students!B$3:F$100,5,FALSE),"")) | H7: =IF(E7="","",E7*IF(F7="",0,F7)-IF(G7="",0,G7)) | L7: =IF(K7="","",IFERROR(VLOOKUP(K7,Scripts!A$3:D$60,3,FALSE),"")) | O7: =IF(K7="","",IFERROR(VLOOKUP(K7,Scripts!A$3:D$60,4,FALSE),""))
D8: =IF(C8="","",IFERROR(VLOOKUP(C8,Students!B$3:F$100,5,FALSE),"")) | H8: =IF(E8="","",E8*IF(F8="",0,F8)-IF(G8="",0,G8)) | L8: =IF(K8="","",IFERROR(VLOOKUP(K8,Scripts!A$3:D$60,3,FALSE),"")) | O8: =IF(K8="","",IFERROR(VLOOKUP(K8,Scripts!A$3:D$60,4,FALSE),""))
D9: =IF(C9="","",IFERROR(VLOOKUP(C9,Students!B$3:F$100,5,FALSE),"")) | H9: =IF(E9="","",E9*IF(F9="",0,F9)-IF(G9="",0,G9)) | L9: =IF(K9="","",IFERROR(VLOOKUP(K9,Scripts!A$3:D$60,3,FALSE),"")) | O9: =IF(K9="","",IFERROR(VLOOKUP(K9,Scripts!A$3:D$60,4,FALSE),""))
D10: =IF(C10="","",IFERROR(VLOOKUP(C10,Students!B$3:F$100,5,FALSE),"")) | H10: =IF(E10="","",E10*IF(F10="",0,F10)-IF(G10="",0,G10)) | L10: =IF(K10="","",IFERROR(VLOOKUP(K10,Scripts!A$3:D$60,3,FALSE),"")) | O10: =IF(K10="","",IFERROR(VLOOKUP(K10,Scripts!A$3:D$60,4,FALSE),""))
D11: =IF(C11="","",IFERROR(VLOOKUP(C11,Students!B$3:F$100,5,FALSE),"")) | H11: =IF(E11="","",E11*IF(F11="",0,F11)-IF(G11="",0,G11)) | L11: =IF(K11="","",IFERROR(VLOOKUP(K11,Scripts!A$3:D$60,3,FALSE),"")) | O11: =IF(K11="","",IFERROR(VLOOKUP(K11,Scripts!A$3:D$60,4,FALSE),""))
D12: =IF(C12="","",IFERROR(VLOOKUP(C12,Students!B$3:F$100,5,FALSE),"")) | H12: =IF(E12="","",E12*IF(F12="",0,F12)-IF(G12="",0,G12)) | L12: =IF(K12="","",IFERROR(VLOOKUP(K12,Scripts!A$3:D$60,3,FALSE),"")) | O12: =IF(K12="","",IFERROR(VLOOKUP(K12,Scripts!A$3:D$60,4,FALSE),""))
D13: =IF(C13="","",IFERROR(VLOOKUP(C13,Students!B$3:F$100,5,FALSE),"")) | H13: =IF(E13="","",E13*IF(F13="",0,F13)-IF(G13="",0,G13)) | L13: =IF(K13="","",IFERROR(VLOOKUP(K13,Scripts!A$3:D$60,3,FALSE),"")) | O13: =IF(K13="","",IFERROR(VLOOKUP(K13,Scripts!A$3:D$60,4,FALSE),""))
D14: =IF(C14="","",IFERROR(VLOOKUP(C14,Students!B$3:F$100,5,FALSE),"")) | H14: =IF(E14="","",E14*IF(F14="",0,F14)-IF(G14="",0,G14)) | L14: =IF(K14="","",IFERROR(VLOOKUP(K14,Scripts!A$3:D$60,3,FALSE),"")) | O14: =IF(K14="","",IFERROR(VLOOKUP(K14,Scripts!A$3:D$60,4,FALSE),""))
D15: =IF(C15="","",IFERROR(VLOOKUP(C15,Students!B$3:F$100,5,FALSE),"")) | H15: =IF(E15="","",E15*IF(F15="",0,F15)-IF(G15="",0,G15)) | L15: =IF(K15="","",IFERROR(VLOOKUP(K15,Scripts!A$3:D$60,3,FALSE),"")) | O15: =IF(K15="","",IFERROR(VLOOKUP(K15,Scripts!A$3:D$60,4,FALSE),""))
... D32: =IF(C32="","",IFERROR(VLOOKUP(C32,Students!B$3:F$100,5,FALSE),"")) | H32: =IF(E32="","",E32*IF(F32="",0,F32)-IF(G32="",0,G32)) | L32: =IF(K32="","",IFERROR(VLOOKUP(K32,Scripts!A$3:D$60,3,FALSE),"")) | O32: =IF(K32="","",IFERROR(VLOOKUP(K32,Scripts!A$3:D$60,4,FALSE),""))
L33: =IF(K33="","",IFERROR(VLOOKUP(K33,Scripts!A$3:D$60,3,FALSE),"")) | O33: =IF(K33="","",IFERROR(VLOOKUP(K33,Scripts!A$3:D$60,4,FALSE),""))
G34: TOTAL | H34: =SUM(H3:H32) -> 8000 | L34: =IF(K34="","",IFERROR(VLOOKUP(K34,Scripts!A$3:D$60,3,FALSE),"")) | O34: =IF(K34="","",IFERROR(VLOOKUP(K34,Scripts!A$3:D$60,4,FALSE),""))

Sheet Expenses
A1: Expenses | G1: =HYPERLINK("#'Cover'!A1","←") -> ←
A2: Date | B2: Item | C2: Category | D2: Amount | E2: Note | F2: Approved by
C34: TOTAL | D34: =SUM(D3:D32) -> 0

Sheet Makeup_Churn
A1: Make-ups & At-Risk | H1: =HYPERLINK("#'Cover'!A1","←") -> ←
A2: Student | B2: Absence dates | C2: Absences | D2: Make-up date | E2: Done | F2: Alert | G2: Message
F4: =IF(C4="","",IF(C4>=2,"At risk — talk now",IF(C4>=1,"Watch","OK"))) | G4: =IF(F4="At risk — talk now",IFERROR(VLOOKUP("M2",Scripts!A$3:D$60,3,FALSE),""),IF(F4="Watch",IFERROR(VLOOKUP("M1",Scripts!A$3:D$60,3,FALSE),""),""))
F5: =IF(C5="","",IF(C5>=2,"At risk — talk now",IF(C5>=1,"Watch","OK"))) | G5: =IF(F5="At risk — talk now",IFERROR(VLOOKUP("M2",Scripts!A$3:D$60,3,FALSE),""),IF(F5="Watch",IFERROR(VLOOKUP("M1",Scripts!A$3:D$60,3,FALSE),""),""))
F6: =IF(C6="","",IF(C6>=2,"At risk — talk now",IF(C6>=1,"Watch","OK"))) | G6: =IF(F6="At risk — talk now",IFERROR(VLOOKUP("M2",Scripts!A$3:D$60,3,FALSE),""),IF(F6="Watch",IFERROR(VLOOKUP("M1",Scripts!A$3:D$60,3,FALSE),""),""))
F7: =IF(C7="","",IF(C7>=2,"At risk — talk now",IF(C7>=1,"Watch","OK"))) | G7: =IF(F7="At risk — talk now",IFERROR(VLOOKUP("M2",Scripts!A$3:D$60,3,FALSE),""),IF(F7="Watch",IFERROR(VLOOKUP("M1",Scripts!A$3:D$60,3,FALSE),""),""))
F8: =IF(C8="","",IF(C8>=2,"At risk — talk now",IF(C8>=1,"Watch","OK"))) | G8: =IF(F8="At risk — talk now",IFERROR(VLOOKUP("M2",Scripts!A$3:D$60,3,FALSE),""),IF(F8="Watch",IFERROR(VLOOKUP("M1",Scripts!A$3:D$60,3,FALSE),""),""))
F9: =IF(C9="","",IF(C9>=2,"At risk — talk now",IF(C9>=1,"Watch","OK"))) | G9: =IF(F9="At risk — talk now",IFERROR(VLOOKUP("M2",Scripts!A$3:D$60,3,FALSE),""),IF(F9="Watch",IFERROR(VLOOKUP("M1",Scripts!A$3:D$60,3,FALSE),""),""))
F10: =IF(C10="","",IF(C10>=2,"At risk — talk now",IF(C10>=1,"Watch","OK"))) | G10: =IF(F10="At risk — talk now",IFERROR(VLOOKUP("M2",Scripts!A$3:D$60,3,FALSE),""),IF(F10="Watch",IFERROR(VLOOKUP("M1",Scripts!A$3:D$60,3,FALSE),""),""))
F11: =IF(C11="","",IF(C11>=2,"At risk — talk now",IF(C11>=1,"Watch","OK"))) | G11: =IF(F11="At risk — talk now",IFERROR(VLOOKUP("M2",Scripts!A$3:D$60,3,FALSE),""),IF(F11="Watch",IFERROR(VLOOKUP("M1",Scripts!A$3:D$60,3,FALSE),""),""))
F12: =IF(C12="","",IF(C12>=2,"At risk — talk now",IF(C12>=1,"Watch","OK"))) | G12: =IF(F12="At risk — talk now",IFERROR(VLOOKUP("M2",Scripts!A$3:D$60,3,FALSE),""),IF(F12="Watch",IFERROR(VLOOKUP("M1",Scripts!A$3:D$60,3,FALSE),""),""))
F13: =IF(C13="","",IF(C13>=2,"At risk — talk now",IF(C13>=1,"Watch","OK"))) | G13: =IF(F13="At risk — talk now",IFERROR(VLOOKUP("M2",Scripts!A$3:D$60,3,FALSE),""),IF(F13="Watch",IFERROR(VLOOKUP("M1",Scripts!A$3:D$60,3,FALSE),""),""))
F14: =IF(C14="","",IF(C14>=2,"At risk — talk now",IF(C14>=1,"Watch","OK"))) | G14: =IF(F14="At risk — talk now",IFERROR(VLOOKUP("M2",Scripts!A$3:D$60,3,FALSE),""),IF(F14="Watch",IFERROR(VLOOKUP("M1",Scripts!A$3:D$60,3,FALSE),""),""))
F15: =IF(C15="","",IF(C15>=2,"At risk — talk now",IF(C15>=1,"Watch","OK"))) | G15: =IF(F15="At risk — talk now",IFERROR(VLOOKUP("M2",Scripts!A$3:D$60,3,FALSE),""),IF(F15="Watch",IFERROR(VLOOKUP("M1",Scripts!A$3:D$60,3,FALSE),""),""))
... F32: =IF(C32="","",IF(C32>=2,"At risk — talk now",IF(C32>=1,"Watch","OK"))) | G32: =IF(F32="At risk — talk now",IFERROR(VLOOKUP("M2",Scripts!A$3:D$60,3,FALSE),""),IF(F32="Watch",IFERROR(VLOOKUP("M1",Scripts!A$3:D$60,3,FALSE),""),""))
G33: =IF(F33="At risk — talk now",IFERROR(VLOOKUP("M2",Scripts!A$3:D$60,3,FALSE),""),IF(F33="Watch",IFERROR(VLOOKUP("M1",Scripts!A$3:D$60,3,FALSE),""),""))
G34: =IF(F34="At risk — talk now",IFERROR(VLOOKUP("M2",Scripts!A$3:D$60,3,FALSE),""),IF(F34="Watch",IFERROR(VLOOKUP("M1",Scripts!A$3:D$60,3,FALSE),""),""))
G35: =IF(F35="At risk — talk now",IFERROR(VLOOKUP("M2",Scripts!A$3:D$60,3,FALSE),""),IF(F35="Watch",IFERROR(VLOOKUP("M1",Scripts!A$3:D$60,3,FALSE),""),""))
G36: =IF(F36="At risk — talk now",IFERROR(VLOOKUP("M2",Scripts!A$3:D$60,3,FALSE),""),IF(F36="Watch",IFERROR(VLOOKUP("M1",Scripts!A$3:D$60,3,FALSE),""),""))
G37: =IF(F37="At risk — talk now",IFERROR(VLOOKUP("M2",Scripts!A$3:D$60,3,FALSE),""),IF(F37="Watch",IFERROR(VLOOKUP("M1",Scripts!A$3:D$60,3,FALSE),""),""))
G38: =IF(F38="At risk — talk now",IFERROR(VLOOKUP("M2",Scripts!A$3:D$60,3,FALSE),""),IF(F38="Watch",IFERROR(VLOOKUP("M1",Scripts!A$3:D$60,3,FALSE),""),""))
G39: =IF(F39="At risk — talk now",IFERROR(VLOOKUP("M2",Scripts!A$3:D$60,3,FALSE),""),IF(F39="Watch",IFERROR(VLOOKUP("M1",Scripts!A$3:D$60,3,FALSE),""),""))
G40: =IF(F40="At risk — talk now",IFERROR(VLOOKUP("M2",Scripts!A$3:D$60,3,FALSE),""),IF(F40="Watch",IFERROR(VLOOKUP("M1",Scripts!A$3:D$60,3,FALSE),""),""))
G41: =IF(F41="At risk — talk now",IFERROR(VLOOKUP("M2",Scripts!A$3:D$60,3,FALSE),""),IF(F41="Watch",IFERROR(VLOOKUP("M1",Scripts!A$3:D$60,3,FALSE),""),""))
G42: =IF(F42="At risk — talk now",IFERROR(VLOOKUP("M2",Scripts!A$3:D$60,3,FALSE),""),IF(F42="Watch",IFERROR(VLOOKUP("M1",Scripts!A$3:D$60,3,FALSE),""),""))
G43: =IF(F43="At risk — talk now",IFERROR(VLOOKUP("M2",Scripts!A$3:D$60,3,FALSE),""),IF(F43="Watch",IFERROR(VLOOKUP("M1",Scripts!A$3:D$60,3,FALSE),""),""))
G44: =IF(F44="At risk — talk now",IFERROR(VLOOKUP("M2",Scripts!A$3:D$60,3,FALSE),""),IF(F44="Watch",IFERROR(VLOOKUP("M1",Scripts!A$3:D$60,3,FALSE),""),""))
... G100: =IF(F100="At risk — talk now",IFERROR(VLOOKUP("M2",Scripts!A$3:D$60,3,FALSE),""),IF(F100="Watch",IFERROR(VLOOKUP("M1",Scripts!A$3:D$60,3,FALSE),""),""))

Sheet Events
A1: Events & Materials | H1: =HYPERLINK("#'Cover'!A1","←") -> ←
A2: Event | B2: Item | C2: Qty | D2: Unit price | E2: Subtotal | F2: Owner | G2: Done?
A3: CCA closing gift | C3: 30 | D3: 50 | E3: =IF(C3="","",C3*D3) -> 1500
A4: Halloween | B4: Pumpkin + decor | C4: 2 | D4: 2000 | E4: =IF(C4="","",C4*D4) -> 4000
A5: Winter camp | B5: Poster flyer | C5: 100 | D5: 15 | E5: =IF(C5="","",C5*D5) -> 1500
E6: =IF(C6="","",C6*D6)
E7: =IF(C7="","",C7*D7)
E8: =IF(C8="","",C8*D8)
E9: =IF(C9="","",C9*D9)
E10: =IF(C10="","",C10*D10)
E11: =IF(C11="","",C11*D11)
E12: =IF(C12="","",C12*D12)
E13: =IF(C13="","",C13*D13)
E14: =IF(C14="","",C14*D14)
E15: =IF(C15="","",C15*D15)
E16: =IF(C16="","",C16*D16)
E17: =IF(C17="","",C17*D17)
... E32: =IF(C32="","",C32*D32)

Sheet WinterCamp
A1: Winter Camp | I1: =HYPERLINK("#'Cover'!A1","←") -> ←
A2: Child | B2: School | C2: Week | D2: Returning | E2: Fee | F2: Paid | G2: Fill | H2: Notes
E3: =IF(A3="","",9000)
E4: =IF(A4="","",9000) | G4: =IF(C4="","",IF(COUNTIF(C$3:C$50,C4)>=4,"Full",""&(4-COUNTIF(C$3:C$50,C4))&" kids"))
E5: =IF(A5="","",9000) | G5: =IF(C5="","",IF(COUNTIF(C$3:C$50,C5)>=4,"Full",""&(4-COUNTIF(C$3:C$50,C5))&" kids"))
E6: =IF(A6="","",9000) | G6: =IF(C6="","",IF(COUNTIF(C$3:C$50,C6)>=4,"Full",""&(4-COUNTIF(C$3:C$50,C6))&" kids"))
E7: =IF(A7="","",9000) | G7: =IF(C7="","",IF(COUNTIF(C$3:C$50,C7)>=4,"Full",""&(4-COUNTIF(C$3:C$50,C7))&" kids"))
E8: =IF(A8="","",9000) | G8: =IF(C8="","",IF(COUNTIF(C$3:C$50,C8)>=4,"Full",""&(4-COUNTIF(C$3:C$50,C8))&" kids"))
E9: =IF(A9="","",9000) | G9: =IF(C9="","",IF(COUNTIF(C$3:C$50,C9)>=4,"Full",""&(4-COUNTIF(C$3:C$50,C9))&" kids"))
E10: =IF(A10="","",9000) | G10: =IF(C10="","",IF(COUNTIF(C$3:C$50,C10)>=4,"Full",""&(4-COUNTIF(C$3:C$50,C10))&" kids"))
E11: =IF(A11="","",9000) | G11: =IF(C11="","",IF(COUNTIF(C$3:C$50,C11)>=4,"Full",""&(4-COUNTIF(C$3:C$50,C11))&" kids"))
E12: =IF(A12="","",9000) | G12: =IF(C12="","",IF(COUNTIF(C$3:C$50,C12)>=4,"Full",""&(4-COUNTIF(C$3:C$50,C12))&" kids"))
E13: =IF(A13="","",9000) | G13: =IF(C13="","",IF(COUNTIF(C$3:C$50,C13)>=4,"Full",""&(4-COUNTIF(C$3:C$50,C13))&" kids"))
E14: =IF(A14="","",9000) | G14: =IF(C14="","",IF(COUNTIF(C$3:C$50,C14)>=4,"Full",""&(4-COUNTIF(C$3:C$50,C14))&" kids"))
E15: =IF(A15="","",9000) | G15: =IF(C15="","",IF(COUNTIF(C$3:C$50,C15)>=4,"Full",""&(4-COUNTIF(C$3:C$50,C15))&" kids"))
... E100: =IF(A100="","",9000) | G100: =IF(C100="","",IF(COUNTIF(C$3:C$50,C100)>=4,"Full",""&(4-COUNTIF(C$3:C$50,C100))&" kids"))

Sheet Camp_Plan
A1: Winter Camp Plan | G1: =HYPERLINK("#'Cover'!A1","←") -> ←
A2: Milestone | B2: Item | C2: Owner | D2: Done? | E2: Notes | F2: Script
A4: Dec | B4: W1 Christmas week — dates locked with parents/schools | E4: 3 weeks total per model; Jan counts 3
A5: Dec | B5: W2 New Year week | E5: Goats-in-Art all 3 weeks
A6: Jan | B6: W3 after-New-Year week | E6: Min 4 kids/week to open
A7: Nov | B7: Goat sculpture Proof standing in the studio (kids see it, want it) | E7: Danny designs
A8: Nov | B8: Week split: sculpture ~12h + painting ~8h = 20h (5 days x 6h incl lunch, 2 breaks) | E8: Topic-focused, one theme
A9: Nov | B9: Daily rule: finished work to take home every day
A10: Nov | B10: Fee CNY 9,000/kid/week; list-price story 400/hr; early-bird + royalty discounts only, each in writing | C10: Approvals | E10: Strict pricing; private rates stay private | F10: F1
A11: Early Dec | B11: Ask regulars staying in Shanghai with K1 (soft, chat-first); invite them to refer a friend staying too | E11: No hard sell | F11: K1
A12: Mid Dec | B12: 100 flyers + QR out
A13: 1 wk before | B13: Headcount per week: 4+ open; under 4 merge into the studio group (studio rent CNY 1,000/day line) | E13: Few kids = studio, not school site
A14: 1 wk before | B14: Roles: Teacher + Helper; lunch plan; materials kits in Events
A15: Camp open | B15: Film with V1 consents only (white canvas to finish) | E15: No signed row, no camera | F15: V1
A16: T+1 day | B16: Thank-you + trial/enrolment pack to every camp family; log in Trials/Leads | E16: 24h rule | F16: T1

Sheet Scripts
A1: Messages | E1: =HYPERLINK("#'Cover'!A1","←") -> ←
A2: No. | B2: Scenario | C2: Message (EN) | D2: Message (CN)
A3: P1 | B3: Send invoice | C3: Hello [name], attached is [child]'s fee summary for [dates]: [n] sessions, CNY [amount]. At NovArt every session is planned around your child, so no two classes are the same. Let me know if you'd like anything adjusted. | D3: 您好[称呼]，附件是[孩子][日期]的费用小结：共[n]节，合计[金额]元。在NovArt，每节课都围绕孩子单独设计，不会有两节完全一样的课。如需调整，随时告诉我。
A4: P2 | B4: Gentle nudge | C4: Hello [name], floating last week's fee summary back to the top — it may be buried in a busy inbox. No rush; reply when it suits you and I'll resend the breakdown. | D4: 您好[称呼]，把上周的费用小结再顶一下，可能沉在未读里了。不着急，方便时回我一声，我把明细再发一份。
A5: T1 | B5: Post-trial 24h | C5: It was lovely having [child] today — [one concrete thing they did]. The course plan is attached; confirming this week keeps the same teacher and slot from next week. | D5: 今天[孩子]表现很好，[一件具体的事]。课程方案附后，本周确认的话，下周起是同一位老师、同一个时间，孩子不用重新适应。
A6: T2 | B6: Trial passed | C6: No pressure at all — art can't be rushed. If you have a moment, tell me what held you back (timing, fee, or simply not yet) so I can note it. When a camp or workshop fits, you'll hear from me first. | D6: 完全没关系，艺术急不得。方便的话告诉我一声，是时间、费用，还是时机未到，我记下来。以后有合适的营或工坊，我第一个告诉您。
A7: R1 | B7: Renewal | C7: Heads-up: [child] has 2 sessions left, finishing around [date]. The next block brings a new artist and new techniques, and the teacher already has a direction in mind for [child]. Shall I hold the slot? | D7: 提醒一下，[孩子]还剩2节，大约[日期]结课。下一轮是新的艺术家和新技法，老师已经给[孩子]想好了方向。需要我把名额留住吗？
A8: M1 | B8: Make-up | C8: We missed [child] today — hope all is well. Would Saturday or Sunday work for a make-up? Send me a time and I'll book it with the teacher. | D8: 今天没见到[孩子]，希望一切都好。周六或周日方便补课吗？给我一个时间，我去跟老师约好。
A9: M2 | B9: At-risk check | C9: We haven't seen [child] for two weeks — is the current time still working? Tell me a better slot and I'll move things around. [Child] was just finding their stride; stopping now would be a pity. | D9: 两周没见到[孩子]了，现在的时间还方便吗？告诉我更合适的时间，我来调整。孩子刚找到感觉，这时候停下来挺可惜的。
A10: C1 | B10: CCA to studio | C10: You're warmly invited: our end-of-term mini exhibition opens Saturday afternoon, and [child] has work in it. Come hear them talk it through for five minutes — grandparents very welcome too. Afterwards, come upstairs and see the studio. | D10: 诚挚邀请：结课小展周六下午开幕，[孩子]有作品参展。欢迎来听孩子讲五分钟，祖父母也一起来。展后欢迎上楼参观工作室。
A11: G1 | B11: Referral ask | C11: If friends ever ask about art classes, feel free to pass along our referral card. Every referring family gets a thank-you, arranged privately. Most of our families found us this way. | D11: 如果朋友问起艺术课，欢迎把我们的引荐卡转给他们。每位转介绍的家庭都有心意，私下安排。我们大部分家庭都是这样来的。
A12: V1 | B12: Photo consent | C12: We'd love to include [child]'s best moments in this week's short film, posted only on our official account. Close-ups always need your OK first — the consent form is attached, and a 'no' on any line is fully respected. | D12: 想把[孩子]本周的精彩瞬间放进本周短片，只发官方账号。特写镜头一定先征得您的同意，授权书附后，任何一条写“不同意”，我们都照办。
A13: S1 | B13: Showcase invite | C13: You're invited to our art get-together this Saturday afternoon. Each child presents their work for about five minutes — grandparents warmly welcome. Hope to see you there. | D13: 邀请您参加本周六下午的艺术小聚。每个孩子上台讲五分钟自己的作品，欢迎祖父母一起来。期待见到您。
... A18: U1 | B18: Second nudge (firm) | C18: Hello [name], following up on the [date] summary (CNY [amount]) — still open. If timing is the issue, give me a date and I'll note it. Otherwise please settle this week so [child]'s classes run uninterrupted. | D18: 您好[称呼]，[日期]的费用单（[金额]元）还没结。如果是付款时间的问题，告诉我一个日期，我记下来。不然的话，麻烦本周结一下，孩子上课不受影响。

Sheet Send_Kit
A1: Send Kit | E1: =HYPERLINK("#'Cover'!A1","←") -> ←
A2: Scenario (pick) | B2: Trial invite
A3: 1 Script (copy) | B3: =IF($B$2="","",CHOOSE(MATCH($B$2,{"First touch";"Trial invite";"Post-trial";"Invoice";"Renewal";"CCA convert";"Referral"},0),"C1: Scripts C1 bilingual","T1: Scripts T1","T1 enrolled / T2 passed: Scripts","P1: Scripts P1","R1: Scripts R1","C1: Scripts C1","G1: Scripts G1")) -> T1: Scripts T1
A4: 2 Flyer (SKU) | B4: =IF($B$2="","",CHOOSE(MATCH($B$2,{"First touch";"Trial invite";"Post-trial";"Invoice";"Renewal";"CCA convert";"Referral"},0),"M-01 trial flyer","M-01 trial flyer","M-01 + M-03 booklet","M-03 booklet + invoice no.","M-02 calendar + new invoice","M-01 + M-06 closing gift","M-04 referral card")) -> M-01 trial flyer
A5: 3 Invoice (which) | B5: =IF($B$2="","",CHOOSE(MATCH($B$2,{"First touch";"Trial invite";"Post-trial";"Invoice";"Renewal";"CCA convert";"Referral"},0),"No invoice yet","No invoice yet","Optional","Invoice no. in Invoices","New invoice","No invoice yet","Invoice on sign-up")) -> No invoice yet
A6: 4 Checklist | B6: =IF($B$2="","",CHOOSE(MATCH($B$2,{"First touch";"Trial invite";"Post-trial";"Invoice";"Renewal";"CCA convert";"Referral"},0),"Ask age/school/time/budget","Lock room + teacher + reminder","Follow up in 24h, log reason","Discount signed?","2 sessions left, renew now","Consent signed?","10% explained?")) -> Lock room + teacher + reminder
A7: → Script (auto) | B7: =B5 -> No invoice yet
A8: → Flyer (auto) | B8: =B6 -> Lock room + teacher + reminder

Sheet Programs
A1: Programs | H1: =HYPERLINK("#'Cover'!A1","←") -> ←
A2: Semester | B2: Program / Artist | C2: Technique | D2: Hours | E2: Status | F2: Fee | G2: Notes
A3: 2026 Fall
A4: 2026 Fall | B4: Architecture | C4: Construction | D4: 8 | E4: Running | G4: Boats — kids love it
A5: 2027 Q1 | B5: Goats in Art (New Year) | C5: Sculpture | D5: 12 | E5: Planned | G5: Danny designs
A6: 2027 Q1 | B6: Cyanotype | C6: Photographic print | D6: 8 | E6: Planned | G6: Marita Wai style
A7: 2027 Q2 | B7: Romero Britto | C7: Painting | D7: 8 | E7: Idea | G7: girlish — popular
A8: 2027 Q2 | B8: Giacometti | C8: Sculpture | D8: 8 | E8: Idea | G8: hard — small groups
A33: CONFIDENTIAL — studio property. Never share full roadmap outside. Version dated on each edit. | B33: Last updated: | C33: =TODAY() -> 46309

Sheet Exhibitions
A1: Exhibitions | K1: =HYPERLINK("#'Cover'!A1","←") -> ←
A2: Name | B2: Date | C2: Organizer cut | D2: Kids | E2: Group | F2: Package fee | G2: Costs covered | H2: Status | I2: Agreed cut % | J2: Contract
A3: HK show
A4: Next exhibition | B4: 2027-01 | C4: tbc — ask Beijing lady | E4: Exhibition-only | H4: Plan - Amber bridge

Sheet Certificates
A1: Certificates | G1: =HYPERLINK("#'Cover'!A1","←") -> ←
A2: Student | B2: Program / Artist | C2: Hours | D2: Technique | E2: Issued | F2: Signed
A3: e.g. Daphne | B3: Morandi | C3: 8 | D3: Painting

Sheet Channel_Pivot
A1: Channels and Revenue | I1: =HYPERLINK("#'Cover'!A1","←") -> ←
A2: Source | B2: Leads | C2: Contacting | D2: Trial booked | E2: Enrolled | F2: Parked | G2: Conv. | H2: Revenue ¥
A3: CCA showcase | B3: =COUNTIF(Leads!E3:E100,A3) -> 1 | C3: =COUNTIFS(Leads!E3:E100,A3,Leads!G3:G100,"Contacting") -> 1 | D3: =COUNTIFS(Leads!E3:E100,A3,Leads!G3:G100,"Trial booked") -> 0 | E3: =COUNTIFS(Leads!E3:E100,A3,Leads!G3:G100,"Enrolled") -> 0 | F3: =COUNTIFS(Leads!E3:E100,A3,Leads!G3:G100,"Parked") -> 0 | G3: =IFERROR(E3/B3,0) -> 0 | H3: =SUMIFS(Invoices!H3:H34,Invoices!M3:M34,A3,Invoices!I3:I34,"Paid") -> 0
A4: School event | B4: =COUNTIF(Leads!E3:E100,A4) -> 0 | C4: =COUNTIFS(Leads!E3:E100,A4,Leads!G3:G100,"Contacting") -> 0 | D4: =COUNTIFS(Leads!E3:E100,A4,Leads!G3:G100,"Trial booked") -> 0 | E4: =COUNTIFS(Leads!E3:E100,A4,Leads!G3:G100,"Enrolled") -> 0 | F4: =COUNTIFS(Leads!E3:E100,A4,Leads!G3:G100,"Parked") -> 0 | G4: =IFERROR(E4/B4,0) -> 0 | H4: =SUMIFS(Invoices!H3:H34,Invoices!M3:M34,A4,Invoices!I3:I34,"Paid") -> 0
A5: Referral | B5: =COUNTIF(Leads!E3:E100,A5) -> 1 | C5: =COUNTIFS(Leads!E3:E100,A5,Leads!G3:G100,"Contacting") -> 0 | D5: =COUNTIFS(Leads!E3:E100,A5,Leads!G3:G100,"Trial booked") -> 0 | E5: =COUNTIFS(Leads!E3:E100,A5,Leads!G3:G100,"Enrolled") -> 1 | F5: =COUNTIFS(Leads!E3:E100,A5,Leads!G3:G100,"Parked") -> 0 | G5: =IFERROR(E5/B5,0) -> 1 | H5: =SUMIFS(Invoices!H3:H34,Invoices!M3:M34,A5,Invoices!I3:I34,"Paid") -> 8000
A6: Walk-in | B6: =COUNTIF(Leads!E3:E100,A6) -> 0 | C6: =COUNTIFS(Leads!E3:E100,A6,Leads!G3:G100,"Contacting") -> 0 | D6: =COUNTIFS(Leads!E3:E100,A6,Leads!G3:G100,"Trial booked") -> 0 | E6: =COUNTIFS(Leads!E3:E100,A6,Leads!G3:G100,"Enrolled") -> 0 | F6: =COUNTIFS(Leads!E3:E100,A6,Leads!G3:G100,"Parked") -> 0 | G6: =IFERROR(E6/B6,0) -> 0 | H6: =SUMIFS(Invoices!H3:H34,Invoices!M3:M34,A6,Invoices!I3:I34,"Paid") -> 0
A7: Social | B7: =COUNTIF(Leads!E3:E100,A7) -> 0 | C7: =COUNTIFS(Leads!E3:E100,A7,Leads!G3:G100,"Contacting") -> 0 | D7: =COUNTIFS(Leads!E3:E100,A7,Leads!G3:G100,"Trial booked") -> 0 | E7: =COUNTIFS(Leads!E3:E100,A7,Leads!G3:G100,"Enrolled") -> 0 | F7: =COUNTIFS(Leads!E3:E100,A7,Leads!G3:G100,"Parked") -> 0 | G7: =IFERROR(E7/B7,0) -> 0 | H7: =SUMIFS(Invoices!H3:H34,Invoices!M3:M34,A7,Invoices!I3:I34,"Paid") -> 0
A8: EKA | B8: =COUNTIF(Leads!E3:E100,A8) -> 0 | C8: =COUNTIFS(Leads!E3:E100,A8,Leads!G3:G100,"Contacting") -> 0 | D8: =COUNTIFS(Leads!E3:E100,A8,Leads!G3:G100,"Trial booked") -> 0 | E8: =COUNTIFS(Leads!E3:E100,A8,Leads!G3:G100,"Enrolled") -> 0 | F8: =COUNTIFS(Leads!E3:E100,A8,Leads!G3:G100,"Parked") -> 0 | G8: =IFERROR(E8/B8,0) -> 0 | H8: =SUMIFS(Invoices!H3:H34,Invoices!M3:M34,A8,Invoices!I3:I34,"Paid") -> 0
A9: Partner | B9: =COUNTIF(Leads!E3:E100,A9) -> 0 | C9: =COUNTIFS(Leads!E3:E100,A9,Leads!G3:G100,"Contacting") -> 0 | D9: =COUNTIFS(Leads!E3:E100,A9,Leads!G3:G100,"Trial booked") -> 0 | E9: =COUNTIFS(Leads!E3:E100,A9,Leads!G3:G100,"Enrolled") -> 0 | F9: =COUNTIFS(Leads!E3:E100,A9,Leads!G3:G100,"Parked") -> 0 | G9: =IFERROR(E9/B9,0) -> 0 | H9: =SUMIFS(Invoices!H3:H34,Invoices!M3:M34,A9,Invoices!I3:I34,"Paid") -> 0
A10: Birthday WS | B10: =COUNTIF(Leads!E3:E100,A10) -> 0 | C10: =COUNTIFS(Leads!E3:E100,A10,Leads!G3:G100,"Contacting") -> 0 | D10: =COUNTIFS(Leads!E3:E100,A10,Leads!G3:G100,"Trial booked") -> 0 | E10: =COUNTIFS(Leads!E3:E100,A10,Leads!G3:G100,"Enrolled") -> 0 | F10: =COUNTIFS(Leads!E3:E100,A10,Leads!G3:G100,"Parked") -> 0 | G10: =IFERROR(E10/B10,0) -> 0 | H10: =SUMIFS(Invoices!H3:H34,Invoices!M3:M34,A10,Invoices!I3:I34,"Paid") -> 0
A11: TOTAL | B11: =SUM(B3:B10) -> 2 | C11: =SUM(C3:C10) -> 1 | D11: =SUM(D3:D10) -> 0 | E11: =SUM(E3:E10) -> 1 | F11: =SUM(F3:F10) -> 0 | G11: =IFERROR(E11/B11,0) -> 0.5 | H11: =SUM(H3:H10) -> 8000
A12: Month | B12: Revenue (paid)
A13: 2026-10 | B13: =SUMIFS(Invoices!H3:H34,Invoices!B3:B34,">="&DATE(2026,10,1),Invoices!B3:B34,"<"&DATE(2026,11,1),Invoices!I3:I34,"Paid") -> 0
A14: 2026-11 | B14: =SUMIFS(Invoices!H3:H34,Invoices!B3:B34,">="&DATE(2026,11,1),Invoices!B3:B34,"<"&DATE(2026,12,1),Invoices!I3:I34,"Paid") -> 0
A15: 2026-12 | B15: =SUMIFS(Invoices!H3:H34,Invoices!B3:B34,">="&DATE(2026,12,1),Invoices!B3:B34,"<"&DATE(2027,1,1),Invoices!I3:I34,"Paid") -> 0
A16: 2027-01 | B16: =SUMIFS(Invoices!H3:H34,Invoices!B3:B34,">="&DATE(2027,1,1),Invoices!B3:B34,"<"&DATE(2027,2,1),Invoices!I3:I34,"Paid") -> 0
A17: 2027-02 | B17: =SUMIFS(Invoices!H3:H34,Invoices!B3:B34,">="&DATE(2027,2,1),Invoices!B3:B34,"<"&DATE(2027,3,1),Invoices!I3:I34,"Paid") -> 0
A18: 2027-03 | B18: =SUMIFS(Invoices!H3:H34,Invoices!B3:B34,">="&DATE(2027,3,1),Invoices!B3:B34,"<"&DATE(2027,4,1),Invoices!I3:I34,"Paid") -> 0
A19: 2027-04 | B19: =SUMIFS(Invoices!H3:H34,Invoices!B3:B34,">="&DATE(2027,4,1),Invoices!B3:B34,"<"&DATE(2027,5,1),Invoices!I3:I34,"Paid") -> 0
A20: 2027-05 | B20: =SUMIFS(Invoices!H3:H34,Invoices!B3:B34,">="&DATE(2027,5,1),Invoices!B3:B34,"<"&DATE(2027,6,1),Invoices!I3:I34,"Paid") -> 0
A21: 2027-06 | B21: =SUMIFS(Invoices!H3:H34,Invoices!B3:B34,">="&DATE(2027,6,1),Invoices!B3:B34,"<"&DATE(2027,7,1),Invoices!I3:I34,"Paid") -> 0
A22: 2027-07 | B22: =SUMIFS(Invoices!H3:H34,Invoices!B3:B34,">="&DATE(2027,7,1),Invoices!B3:B34,"<"&DATE(2027,8,1),Invoices!I3:I34,"Paid") -> 0
A23: 2027-08 | B23: =SUMIFS(Invoices!H3:H34,Invoices!B3:B34,">="&DATE(2027,8,1),Invoices!B3:B34,"<"&DATE(2027,9,1),Invoices!I3:I34,"Paid") -> 0
A24: 2027-09 | B24: =SUMIFS(Invoices!H3:H34,Invoices!B3:B34,">="&DATE(2027,9,1),Invoices!B3:B34,"<"&DATE(2027,10,1),Invoices!I3:I34,"Paid") -> 0

Sheet Access
A1: Access Control — who can see and edit | F1: =HYPERLINK("#'Cover'!A1","←") -> ←
A2: Member | B2: Role | C2: Can view | D2: Can edit | E2: Locked
A3: Coordinator (TBD) | B3: Workbook author (TBD) | C3: All | D3: All (incl formulas) | E3: —
A4: Nicole | B4: Partner | C4: View all | D4: Sign approvals, discount cols | E4: Finance formulas, structure
A5: Danny | B5: Founder + teacher | C5: View all | D5: Programs content, sign-offs | E5: Finance, contact details

Sheet Consents
A1: Consents | H1: =HYPERLINK("#'Cover'!A1","←") -> ←
A2: Student | B2: Photo | C2: Video | D2: Close-up | E2: School publish | F2: Signed date | G2: File ref
A3: e.g. Josh D1 | B3: Yes | C3: Yes | D3: Yes | E3: No | F3: 2026-10-20

Sheet Approvals
A1: Approvals | H1: =HYPERLINK("#'Cover'!A1","←") -> ←
A2: Date | B2: Type | C2: Student/Item | D2: Amount/Discount | E2: Requested by | F2: Approved by | G2: Status
A3: 2026-10-20 | B3: Discount (early bird/loyal) | C3: Josh 4 kids | D3: 10% off | G3: Requested
B4: Exhibition cut | C4: Beijing organizer % | D4: TBD — get it in writing before any entry work starts | G4: Requested
B5: Partnership | C5: EKA points linkage + 2h staff taster | D5: Pending EKA reply (spend/park link; taster format TBD) | G5: Requested

Sheet Offboarding
A1: Offboarding - Run the day someone steps back | E1: =HYPERLINK("#'Cover'!A1","←") -> ←
A2: Step | B2: Owner | C2: Done | D2: Date
A3: 1. Change shared-doc password
A4: 2. Remove personal devices
A5: 3. Confirm all rows = official account
A6: 4. Export final backup
A7: 5. Revoke shares except founders

Sheet Assets
A1: Asset Library — what we have and what is missing | J1: =HYPERLINK("#'Cover'!A1","←") -> ←
A2: No. | B2: Item | C2: Version/Date | D2: Location | E2: Stock/Link | F2: Script | G2: Notes | H2: Cloud link | I2: Status
A3: M-01 | B3: Trial flyer | C3: Nicole ver. | D3: Cloud/Assets | E3: / | F3: =IF(F3="","",VLOOKUP(F3,Scripts!A$3:D$20,3,FALSE)) -> 0 | G3: Attach for trial families | H3: See Flyer sheet; link final from cloud | I3: Ready
A4: M-02 | B4: 2027 calendar + year plan | C4: To design | D4: See Calendar sheet | E4: / | F4: =IF(F4="","",VLOOKUP(F4,Scripts!A$3:D$20,3,FALSE)) -> 0 | G4: Closing + welcome gifts | I4: Ready
A5: M-03 | B5: Program booklet | C5: To compress | D5: Cloud/Assets | E5: / | F5: =IF(F5="","",VLOOKUP(F5,Scripts!A$3:D$20,3,FALSE)) -> 0 | G5: PDF too big — compress first
A6: M-04 | B6: Referral card | C6: To print | D6: Front desk | E6: / | F6: =IF(F6="","",VLOOKUP(F6,Scripts!A$3:D$20,3,FALSE)) -> 0 | G6: Parents pass on
A7: M-05 | B7: Consent form | C7: Final | D7: Front desk + cloud | E7: / | F7: =IF(F7="","",VLOOKUP(F7,Scripts!A$3:D$20,3,FALSE)) -> 0 | G7: Sign first
A8: M-06 | B8: Closing gift pack | C8: To stock | D8: Studio | E8: / | F8: =IF(F8="","",VLOOKUP(F8,Scripts!A$3:D$20,3,FALSE)) -> 0 | G8: sketchbook + stickers + QR
A9: M-07 | B9: Birthday WS poster | C9: To make | D9: Cloud/Assets | E9: / | F9: =IF(F9="","",VLOOKUP(F9,Scripts!A$3:D$20,3,FALSE)) -> 0 | G9: 6–8 kids
A10: M-08 | B10: Winter camp flyer | C10: Theme TBD by Danny | D10: Cloud/Assets | E10: / | F10: =IF(F10="","",VLOOKUP(F10,Scripts!A$3:D$20,3,FALSE)) -> 0 | G10: Goat-year theme first
A11: M-09 | B11: Invoice slip | C11: See Invoice_Poster | D11: This sheet | E11: / | F11: =IF(F11="","",VLOOKUP(F11,Scripts!A$3:D$60,3,FALSE)) -> 0 | G11: Attach with bills
A12: M-10 | B12: Consent form | C12: See Consent_Poster | D12: Front desk + sheet | E12: / | F12: =IF(F12="","",VLOOKUP(F12,Scripts!A$3:D$60,3,FALSE)) -> 0 | G12: Sign first
A13: M-11 | B13: Survey | C13: See Survey_Poster | D13: This sheet | E13: / | F13: =IF(F13="","",VLOOKUP(F13,Scripts!A$3:D$60,3,FALSE)) -> 0 | G13: Send before renewal
A14: M-12 | B14: Halloween flyer | C14: EN HD | D14: See Halloween sheet | E14: / | F14: =IF(F14="","",VLOOKUP(F14,Scripts!A$3:D$60,3,FALSE)) -> 0 | G14: 10-kid groups, scan to book | I14: Ready
A15: M-13 | B15: For Fun EN | C15: EN ver. | D15: See ForFun_EN | E15: / | F15: =IF(F15="","",VLOOKUP(F15,Scripts!A$3:D$60,3,FALSE)) -> 0 | G15: Swap original logo before print
A16: M-14 | B16: Closing gifts | C16: Mid-Nov ver. | D16: Studio | E16: / | F16: =IF(F16="","",VLOOKUP(F16,Scripts!A$3:D$60,3,FALSE)) -> 0 | G16: sketchbook + stickers + pen + QR + red packet
A17: M-15 | B17: Real pumpkins + carving tools | C17: Halloween | D17: Studio | E17: / | F17: =IF(F17="","",VLOOKUP(F17,Scripts!A$3:D$60,3,FALSE)) -> 0 | G17: Buy early

Sheet Brand
A1: Brand Assets — logo, sign-offs, letterhead | D1: =HYPERLINK("#'Cover'!A1","←") -> ←
A2: Item | B2: Standard / Text | C2: Status
A3: Logo | B3: NovArt STUDIO (Λ-A · mirrored-R · F-T); print body always NOVART, art variants for graphics only | C3: TBD
A4: Email sign-off | B4: TBD | Novart Studio · EKA Tianwu, Pudong; Course enquiries | Email TBD | C4: TBD
A5: WeChat sign-off | B5: TBD | Novart Studio; Official account, reply within 1 hour | C5: TBD
A6: Letterhead | B6: NovArt STUDIO (Λ-A · mirrored-R · F-T); print body always NOVART, art variants for graphics only | C6: To design
A7: Business card | B7: Name + official account + Room 409 EKA Tianwu | C7: To print
A8: Receiving account | B8: Corporate account TBD (never use personal accounts) | C8: TBD

Sheet PDF_List
A1: PDF Build List — list first, design later | G1: =HYPERLINK("#'Cover'!A1","←") -> ←
A2: No. | B2: PDF | C2: Use | D2: Source sheet | E2: Status | F2: Notes
A3: PDF-01 | B3: Invoice slip | C3: Bill parents | D3: Invoices | E3: To design | F3: After logo final
A4: PDF-02 | B4: Consent form | C4: Sign first | D4: Consents | E4: To design | F4: One page per child
A5: PDF-03 | B5: Survey | C5: Send before renewal | D5: Certificates | E5: To design | F5: 1–5 scale
A6: PDF-04 | B6: Program booklet | C6: Send to prospects | D6: Programs | E6: To compress | F6: Source PDF too big
A7: PDF-05 | B7: 2027 calendar | C7: Closing + welcome gifts | D7: Calendar | E7: Draft ready | F7: Nicole ver. filed
A8: PDF-06 | B8: Trial flyer | C8: Send to new leads | D8: Leads | E8: Ready | F8: Nicole ver. filed
A9: PDF-07 | B9: Referral card | C9: Referrals | D9: Students | E9: To design | F9: Print 10% rule
A10: PDF-08 | B10: Completion certificate | C10: Renewal hook | D10: Certificates | E10: To design | F10: Signed by Danny

Sheet Calendar
A1: Class Calendar | B1: =HYPERLINK("#'Cover'!A1","←") -> ←

Sheet Halloween
A1: Halloween Flyer | B1: =HYPERLINK("#'Cover'!A1","←") -> ←

Sheet ForFun_EN
A1: ForFun EN | B1: =HYPERLINK("#'Cover'!A1","←") -> ←

Sheet Flyer
A1: Trial Flyer | B1: =HYPERLINK("#'Cover'!A1","←") -> ←

Sheet Tasklist
A1: Tasks | L1: =HYPERLINK("#'Cover'!A1","←") -> ←
A2: Type | B2: Scope | C2: When | D2: Start | E2: End | F2: Hours | G2: Owner | H2: Check A | I2: Check B | J2: Priority | K2: Done%
A3: Mid Nov | B3: Stock closing gifts (sketchbook + stickers + pen + QR + red packet) | C3: Mid Nov | D3: 2026-11 | E3: 2026-11 | F3: 6h | I3: TBD | J3: P0 | K3: 0
A4: Oct | B4: Window + lift ads live in 3 days | C4: This week | D4: 2026-10 | E4: 2026-10 | F4: 1h | H4: TBD | I4: TBD | J4: P0 | K4: 0
A5: Oct | B5: Buy real pumpkins early + count tables | C5: Before Halloween | D5: 2026-10 | E5: 2026-10 | F5: 2h | H5: TBD | I5: TBD | J5: P0 | K5: 0
A6: Monthly | B6: Collect reviews + referrals | C6: Monthly | D6: 2026-11 | E6: 2027-08 | F6: 2h | H6: TBD | I6: TBD | J6: P0 | K6: 0
A7: P0 | B7: UN to NovArt brand cutover: EKA signage, lift ads, parent notice (old name UN Studio) | C7: This week | D7: 2026-10 | E7: 2026-10 | F7: 2h | H7: TBD | I7: TBD | J7: P0 | K7: 0
A8: Cash | B8: Collect Josh 4-kid fees (discount signed, 24h) | C8: Once | D8: 2026-10 | E8: 2026-10 | F8: 4h | H8: TBD | I8: TBD | J8: P0 | K8: 0
A9: Cash | B9: Revive Daphne-type dormant credits (18-class sleepers) | C9: Once | D9: 2026-10 | E9: 2026-10 | F9: 4h | H9: TBD | I9: TBD | J9: P0 | K9: 0
A10: Cash | B10: Clear unpaid list before each camp/term | C10: Each term | D10: 2026-10 | E10: 2027-08 | F10: 2h | I10: TBD | J10: P0 | K10: 0
A11: Sales | B11: Lock 3 open issues before start: CCA TA, trial fee, credit expiry | C11: Once | D11: 2026-10 | E11: 2026-10 | F11: 3h | I11: TBD | J11: P0 | K11: 0
A12: Sales | B12: Lock 400 list price story in T1 (tailor-made defense) | C12: Once | D12: 2026-10 | E12: 2026-10 | F12: 2h | H12: TBD | I12: TBD | J12: P0 | K12: 0
A13: Expansion | B13: New-school CCA (Wellington/Concordia) | C13: 2027 | D13: 2027-01 | E13: 2027-03 | F13: 4h | I13: TBD | J13: P1 | K13: 0
A14: Phase 1-2 wks | B14: Open public email + social accounts + print consent forms | C14: Once | D14: 2026-10 | E14: 2026-10 | F14: 4h | H14: TBD | I14: TBD | J14: P1 | K14: 0
A15: Phase 7-8 wks | B15: Proof calendar booklet + 2027 Q1 plan | C15: Once | D15: 2026-10 | E15: 2026-10 | F15: 8h | H15: TBD | I15: TBD | J15: P1 | K15: 0
A16: Weekly | B16: 1–2 short videos (shoot/edit/post) | C16: Weekly | D16: 2026-10 | E16: 2027-08 | F16: 4h/wk | H16: TBD | I16: TBD | J16: P1 | K16: 0
A17: EKA liaison | B17: EKA points integration (spend/park) | C17: Nov | D17: 2026-11 | E17: 2026-11 | F17: 4h | H17: TBD | I17: TBD | J17: P1 | K17: 0
A18: Exhibitions | B18: Jan show entry + Beijing cut agreed | C18: Jan | D18: 2027-01 | E18: 2027-01 | F18: 4h | H18: TBD | I18: TBD | J18: P1 | K18: 0
A19: Teaching | B19: 5 programs × 8h per term + rebook scripts | C19: Per term | D19: 2027-03 | E19: 2027-06 | F19: 4h | H19: TBD | I19: TBD | J19: P1 | K19: 0
A20: Certificates | B20: Year-1 group + solo shows + certificates | C20: May–Jun | D20: 2027-05 | E20: 2027-06 | F20: 8h | H20: TBD | I20: TBD | J20: P1 | K20: 0
A21: Weekly | B21: Onboarding: schedule + kit + rules + expectations | C21: Weekly | D21: 2026-10 | E21: 2027-08 | F21: 1h | H21: TBD | I21: TBD | J21: P1 | K21: 0
A22: Weekly | B22: Trial end-to-end: welcome + brief + experience | C22: Weekly | D22: 2026-10 | E22: 2027-08 | F22: 2h | H22: TBD | I22: TBD | J22: P1 | K22: 0
A23: Weekly | B23: Referral upkeep: families + partners + schools | C23: Weekly | D23: 2026-10 | E23: 2027-08 | F23: 1h | H23: TBD | I23: TBD | J23: P1 | K23: 0
A24: Weekly | B24: Campaign calendar + flyers + social content | C24: Weekly | D24: 2026-10 | E24: 2027-08 | F24: 3h | H24: TBD | I24: TBD | J24: P1 | K24: 0
A25: P1 | B25: Audit YIQI ART WeChat account: followers, history posts, migrate/rename plan | C25: Nov | D25: 2026-11 | E25: 2026-11 | F25: 3h | J25: P1 | K25: 0
A26: P1 | B26: Catalog PDF slim-down (too big to send) + 2027 calendar inside | C26: Nov | D26: 2026-11 | E26: 2026-11 | F26: 6h | J26: P1 | K26: 0
A27: P1 | B27: Copycat file: Shun Space evidence screenshots archived (defense only) | C27: Once | D27: 2026-11 | E27: 2026-11 | F27: 2h | J27: P1 | K27: 0
A28: P1 | B28: Exhibition pipeline lock: Beijing lady cut %, Amber bridge, Jan show | C28: Jan | D28: 2027-01 | E28: 2027-01 | F28: 4h | I28: TBD | J28: P1 | K28: 0
A29: P1 | B29: Per-artist one-pager: essence + technique + hours (Danny dictates, you format) | C29: Per term | D29: 2027-03 | E29: 2027-06 | F29: 4h | I29: TBD | J29: P1 | K29: 0
A30: Ops | B30: Weekly showcase clips: white canvas to finish + family photo | C30: Weekly | D30: 2026-11 | E30: 2027-08 | F30: 2h/wk | I30: TBD | J30: P1 | K30: 0
A31: Program | B31: 3-year artist roadmap: 200 artists split by term (retention story) | C31: Once | D31: 2026-11 | E31: 2026-12 | F31: 6h | I31: TBD | J31: P1 | K31: 0
A32: Sales | B32: BirthdayWS packages: 6-8 kids, cost-covering, all guests to trials | C32: Per event | D32: 2026-10 | E32: 2027-08 | F32: 2h/session | I32: TBD | J32: P1 | K32: 0
A33: Review | B33: August lesson ritual: lock summer people + money (lost ¥50k) | C33: Each Aug | D33: 2027-08 | E33: 2027-08 | F33: 2h | I33: TBD | J33: P1 | K33: 0
A34: Weekly | B34: Lead + 24h trial follow-up (Wed/Thu eves) | C34: Weekly | D34: 2026-10 | E34: 2027-08 | F34: 4h/wk | H34: TBD | I34: TBD | J34: P2 | K34: 0
A35: Weekly | B35: Attendance/credits/make-ups/churn (Fri) | C35: Weekly | D35: 2026-10 | E35: 2027-08 | F35: 2h/wk | H35: TBD | I35: TBD | J35: P2 | K35: 0
A36: Weekends | B36: Studio TA + reception + filming | C36: Every weekend | D36: 2026-10 | E36: 2027-08 | F36: 8h | I36: TBD | J36: P2 | K36: 0
A37: EKA liaison | B37: Venue + staff taster (2h free) | C37: As needed | D37: 2026-10 | E37: 2027-08 | F37: 2h/session | I37: TBD | J37: P2 | K37: 0
A38: EKA liaison | B38: EKA staff 2h free taster (Kyiv scarf-machine style: simple + fun, format TBD) | C38: As needed | D38: 2026-10 | E38: 2027-08 | F38: 2h/session | H38: TBD | I38: TBD | J38: P2 | K38: 0
A39: New: adults | B39: Adult tasters (materials/venue separate) | C39: TBD | D39: 2027-08 | E39: 2027-08 | F39: 3h/session | H39: TBD | I39: TBD | J39: P2 | K39: 0
A40: New: props | B40: Studio decor (water feature size TBD — passing thought, lowest priority) | C40: End Oct | D40: 2026-10 | E40: 2026-10 | F40: 2h | H40: TBD | I40: TBD | J40: P2 | K40: 0
...

Sheet Invoice_Poster
A1: Invoice Poster | B1: =HYPERLINK("#'Cover'!A1","←") -> ←

Sheet Consent_Poster
A1: Consent Poster | B1: =HYPERLINK("#'Cover'!A1","←") -> ←

Sheet Survey_Poster
A1: Survey Poster | B1: =HYPERLINK("#'Cover'!A1","←") -> ←

Sheet Gantt
